Workbook

Sheet Resumo Executivo
A1: Análise Quantitativa — Fundos High Grade Acessíveis | B1: Análise Quantitativa — Fundos High Grade Acessíveis | C1: Análise Quantitativa — Fundos High Grade Acessíveis | D1: Análise Quantitativa — Fundos High Grade Acessíveis | E1: Análise Quantitativa — Fundos High Grade Acessíveis | F1: Análise Quantitativa — Fundos High Grade Acessíveis | G1: Análise Quantitativa — Fundos High Grade Acessíveis | H1: Análise Quantitativa — Fundos High Grade Acessíveis
A3: Leitura executiva | B3: Leitura executiva | C3: Leitura executiva | D3: Leitura executiva | E3: Leitura executiva | F3: Leitura executiva | G3: Leitura executiva | H3: Leitura executiva
A4: A base possui 53 fundos high grade: 46 fundos de mercado e 7 fundos atualmente investidos pelo cliente. A análise quantitativa indica que a cesta do cliente ficou abaixo do universo comparável nas janelas recentes, principalmente em 12 meses, com maior volatilidade e pior drawdown. A leitura de 24–36 meses ainda é melhor para parte da carteira, mas não compensa integralmente a piora recente ajustada a risco.
A7: Métrica | B7: Mercado — Mediana | C7: Cliente — Mediana | D7: Diferença Cliente vs. Mercado | F7: Conclusões objetivas
A8: Ano (% CDI) | B8: 0.93607216 | C8: 0.79245189 | D8: -0.14362027 | F8: 1. A carteira atual está quantitativamente desfavorecida nas janelas recentes: mediana de 95,1% do CDI em 12M contra 98,7% do CDI no mercado.
A9: 12 Meses (% CDI) | B9: 0.98664852 | C9: 0.95084131 | D9: -0.035807208 | F9: 2. A pior relação risco/retorno está concentrada em SPX Seahawk e AZ Quest Altro, com 12M abaixo de 90% do CDI, Sharpe negativo e rankings no fim da amostra.
A10: 24 Meses (% CDI) | B10: 1.0358203 | C10: 1.0371472 | D10: 0.001326897 | F10: 3. JGP é o melhor nome entre os fundos do cliente, mas ainda não se destaca contra os melhores fundos de mercado por Sharpe e volatilidade.
A11: 36 Meses (% CDI) | B11: 1.0852305 | C11: 1.115647 | D11: 0.030416448 | F11: 4. Porto, Polo e Sparta mantêm histórico de 24–36M acima do CDI, mas a janela de 12M justifica congelar novos aportes até evidência de recuperação.
A12: Volatilidade 12M | B12: 0.0028089457 | C12: 0.0052645791 | D12: 0.0024556334 | F12: 5. Para substituição quantitativa, os melhores candidatos da amostra são Persevera Yield, BNP Rubi, Daycoval Classic 30, SulAmérica Crédito Ativo, BNP Match Plus 30 e Tivio Institucional 15.
A13: Sharpe 12M | B13: -0.50149342 | C13: -1.3884552 | D13: -0.88696177
A14: Drawdown máximo 12M | B14: -0.0012803218 | C14: -0.0024009558 | D14: -0.001120634
A15: Score Quantitativo | B15: 53.533435 | C15: 45.849677 | D15: -7.6837579
A18: Ranking | B18: Fundo | C18: Gestor | D18: Grupo | E18: Liquidez | F18: 12M % CDI | G18: 24M % CDI | H18: 36M % CDI | I18: Vol 12M | J18: Sharpe 12M | K18: Score
A19: 1 | B19: Persevera Yield FIRF LP | C19: Persevera Asset Management | D19: Mercado | E19: 15 | F19: 1.0589278 | G19: 1.0579844 | I19: 0.0013838478 | J19: 5.4687897 | K19: 89.579217
A20: 2 | B20: BNP Paribas Rubi FIF RF CP RL | C20: BNP Paribas Asset Management | D20: Mercado | E20: 10 | F20: 1.034092 | G20: 1.0543423 | H20: 1.0861845 | I20: 0.00080229319 | J20: 5.465681 | K20: 88.648057
A21: 3 | B21: Daycoval Classic 30 FIRF CP | C21: Daycoval Asset Management | D21: Mercado | E21: 30 | F21: 1.0237355 | G21: 1.0522985 | H21: 1.10095 | I21: 0.0018143026 | J21: 1.6846203 | K21: 82.10147
A22: 4 | B22: SulAmérica Crédito Ativo FIRF CP LP | C22: SulAmérica Investimentos | D22: Mercado | E22: 30 | F22: 1.0338814 | G22: 1.072446 | H22: 1.1408274 | I22: 0.0028243912 | J22: 1.5442974 | K22: 80.135356
A23: 5 | B23: BNP Paribas Match Plus 30 Advisory FIF RF CP LP RL | C23: BNP Paribas Asset Management | D23: Mercado | E23: 30 | F23: 1.0260059 | G23: 1.0416889 | I23: 0.00090431071 | J23: 3.7010515 | K23: 79.244253
A24: 6 | B24: Tivio Institucional 15 | C24: Tivio Capital | D24: Mercado | E24: 16 | F24: 1.0185403 | G24: 1.0784637 | H24: 1.1497749 | I24: 0.0028298313 | J24: 0.84490065 | K24: 76.41149
A25: 7 | B25: Bradesco Ultra II FIF - CIC RF CP LP - RL | C25: Bradesco S.A. | D25: Mercado | E25: 31 | F25: 1.0225305 | I25: 0.0019740415 | J25: 1.4700027 | K25: 75.197115
A26: 8 | B26: Mag High Grade Plus 30 FIF RF CP LP RL | C26: Mongeral Aegon Investimentos | D26: Mercado | E26: 31 | F26: 1.0311738 | G26: 1.0364432 | I26: 0.0017909506 | J26: 2.2400288 | K26: 74.034343
A27: 9 | B27: Vinland Crédito 10 FIC FIRF | C27: Vinland Capital Management | D27: Mercado | E27: 10 | F27: 0.99402448 | G27: 1.067606 | I27: 0.0016284689 | J27: -0.47235098 | K27: 73.971899
A28: 10 | B28: Atena Yield D30 FIC de FIF RF CP RL | C28: Atena Capital | D28: Mercado | E28: 30 | F28: 1.0393716 | G28: 1.0358203 | H28: 1.0672421 | I28: 0.0012778347 | J28: 3.9620969 | K28: 73.79742
A29: 11 | B29: SulAmérica Crédito ESG FIRF CP LP IS | C29: SulAmérica Investimentos | D29: Mercado | E29: 46 | F29: 1.0033957 | G29: 1.0651462 | H29: 1.1452215 | I29: 0.001479306 | J29: 0.29654697 | K29: 69.38524
A30: 12 | B30: Bocom BBM Corporate Credit II FIF RF CP RL | C30: BOCOM BBM Investimentos | D30: Mercado | E30: 31 | F30: 1.0135992 | G30: 1.0535864 | I30: 0.0025784676 | J30: 0.68050876 | K30: 67.517569
A31: 13 | B31: BOCOM BBM Corporate Credit Plus FIF CIC MULT CP RL | C31: BOCOM BBM Investimentos | D31: Mercado | E31: 121 | F31: 1.0440933 | G31: 1.0814699 | H31: 1.1212772 | I31: 0.0044325919 | J31: 1.2807941 | K31: 67.504745
A32: 14 | B32: Root Capital Crédito HG Plus FIC de FIF Multimercado CP RL | C32: Root Capital | D32: Mercado | E32: 60 | F32: 1.0159979 | G32: 1.0706601 | H32: 1.1167846 | I32: 0.0019103322 | J32: 1.0792761 | K32: 65.367615
A33: 15 | B33: Novus Crédito FIM CP LP | C33: Novus Crédito Gestão de Recursos Ltda. | D33: Mercado | E33: 31 | F33: 0.99977507 | G33: 1.0552487 | H33: 1.1627683 | I33: 0.0024863877 | J33: -0.01042642 | K33: 64.176752

Sheet Ranking Quantitativo
A1: Ranking Geral | B1: Grupo | C1: Fundo | D1: Gestor | E1: CNPJ | F1: Risco XP | G1: Liquidez | H1: Taxa Adm. | I1: Ano % CDI | J1: 12M % CDI | K1: 24M % CDI | L1: 36M % CDI | M1: Vol 12M | N1: Sharpe 12M | O1: Max DD 12M | P1: Janelas > CDI | Q1: Score Retorno | R1: Score Risco | S1: Score Consistência | T1: Score Liquidez/Custo | U1: Score Final
A2: 1 | B2: Mercado | C2: Persevera Yield FIRF LP | D2: Persevera Asset Management | E2: =INDEX(Sheet1!C:C,MATCH('Ranking Quantitativo'!C2,Sheet1!B:B,0)) -> 51693641000100 | F2: 10 | G2: 15 | H2: 0.007 | I2: 1.0556068 | J2: 1.0589278 | K2: 1.0579844 | M2: 0.0013838478 | N2: 5.4687897 | P2: 3/3 | Q2: 93.877551 | R2: 85.798817 | S2: 100 | T2: 58.846154 | U2: 89.579217
A3: 2 | B3: Mercado | C3: BNP Paribas Rubi FIF RF CP RL | D3: BNP Paribas Asset Management | E3: =INDEX(Sheet1!C:C,MATCH('Ranking Quantitativo'!C3,Sheet1!B:B,0)) -> 21185984000100 | F3: 4 | G3: 10 | H3: 0.004 | I3: 1.0014604 | J3: 1.034092 | K3: 1.0543423 | L3: 1.0861845 | M3: 0.00080229319 | N3: 5.465681 | P3: 4/4 | Q3: 79.17517 | R3: 96.153846 | S3: 98.076923 | T3: 93.653846 | U3: 88.648057
A4: 3 | B4: Mercado | C4: Daycoval Classic 30 FIRF CP | D4: Daycoval Asset Management | E4: =INDEX(Sheet1!C:C,MATCH('Ranking Quantitativo'!C4,Sheet1!B:B,0)) -> 29250121000173 | F4: 3 | G4: 30 | H4: 0.004 | I4: 0.98539291 | J4: 1.0237355 | K4: 1.0522985 | L4: 1.10095 | M4: 0.0018143026 | N4: 1.6846203 | O4: -6.6220064e-05 | P4: 3/4 | Q4: 75.624673 | R4: 89.204545 | S4: 90.384615 | T4: 76.923077 | U4: 82.10147
A5: 4 | B5: Mercado | C5: SulAmérica Crédito Ativo FIRF CP LP | D5: SulAmérica Investimentos | E5: =INDEX(Sheet1!C:C,MATCH('Ranking Quantitativo'!C5,Sheet1!B:B,0)) -> 13823084000105 | F5: 11 | G5: 30 | H5: 0.006 | I5: 0.98605497 | J5: 1.0338814 | K5: 1.072446 | L5: 1.1408274 | M5: 0.0028243912 | N5: 1.5442974 | O5: -0.00010925469 | P5: 3/4 | Q5: 89.489796 | R5: 65.305944 | S5: 88.461538 | T5: 58.461538 | U5: 80.135356
A6: 5 | B6: Mercado | C6: BNP Paribas Match Plus 30 Advisory FIF RF CP LP RL | D6: BNP Paribas Asset Management | E6: =INDEX(Sheet1!C:C,MATCH('Ranking Quantitativo'!C6,Sheet1!B:B,0)) -> 50098505000109 | F6: 11 | G6: 30 | H6: 0.0065 | I6: 0.99104647 | J6: 1.0260059 | K6: 1.0416889 | M6: 0.00090431071 | N6: 3.7010515 | P6: 2/3 | Q6: 77.811028 | R6: 80.91716 | S6: 94.230769 | T6: 51.538462 | U6: 79.244253
A7: 6 | B7: Mercado | C7: Tivio Institucional 15 | D7: Tivio Capital | E7: =INDEX(Sheet1!C:C,MATCH('Ranking Quantitativo'!C7,Sheet1!B:B,0)) -> 04240128000183 | F7: 11 | G7: 16 | H7: 0.005 | I7: 0.92182548 | J7: 1.0185403 | K7: 1.0784637 | L7: 1.1497749 | M7: 0.0028298313 | N7: 0.84490065 | O7: -0.00013747754 | P7: 3/4 | Q7: 82.579147 | R7: 62.84965 | S7: 78.846154 | T7: 77.692308 | U7: 76.41149
A8: 7 | B8: Mercado | C8: Bradesco Ultra II FIF - CIC RF CP LP - RL | D8: Bradesco S.A. | E8: =INDEX(Sheet1!C:C,MATCH('Ranking Quantitativo'!C8,Sheet1!B:B,0)) -> 55315627000123 | F8: 11 | G8: 31 | H8: 0.006 | I8: 0.95253311 | J8: 1.0225305 | M8: 0.0019740415 | N8: 1.4700027 | O8: -4.1677604e-05 | P8: 1/2 | Q8: 76.730769 | R8: 77.211538 | S8: 86.538462 | T8: 40.576923 | U8: 75.197115
A9: 8 | B9: Mercado | C9: Mag High Grade Plus 30 FIF RF CP LP RL | D9: Mongeral Aegon Investimentos | E9: =INDEX(Sheet1!C:C,MATCH('Ranking Quantitativo'!C9,Sheet1!B:B,0)) -> 50697486000137 | F9: 11 | G9: 31 | H9: 0.0064 | I9: 1.0091709 | J9: 1.0311738 | K9: 1.0364432 | M9: 0.0017909506 | N9: 2.2400288 | P9: 3/3 | Q9: 75.983615 | R9: 71.597633 | S9: 92.307692 | T9: 34.807692 | U9: 74.034343
A10: 9 | B10: Mercado | C10: Vinland Crédito 10 FIC FIRF | D10: Vinland Capital Management | E10: =INDEX(Sheet1!C:C,MATCH('Ranking Quantitativo'!C10,Sheet1!B:B,0)) -> 53678015000170 | F10: 10 | G10: 10 | H10: 0.005 | I10: 0.9650206 | J10: 0.99402448 | K10: 1.067606 | M10: 0.0016284689 | N10: -0.47235098 | O10: -0.00014785599 | P10: 1/3 | Q10: 73.8177 | R10: 83.40035 | S10: 55.769231 | T10: 87.5 | U10: 73.971899
A11: 10 | B11: Mercado | C11: Atena Yield D30 FIC de FIF RF CP RL | D11: Atena Capital | E11: =INDEX(Sheet1!C:C,MATCH('Ranking Quantitativo'!C11,Sheet1!B:B,0)) -> 31340838000158 | F11: 11 | G11: 30 | H11: 0.0085 | I11: 1.024333 | J11: 1.0393716 | K11: 1.0358203 | L11: 1.0672421 | M11: 0.0012778347 | N11: 3.9620969 | P11: 4/4 | Q11: 68.297357 | R11: 78.254438 | S11: 96.153846 | T11: 42.692308 | U11: 73.79742
A12: 11 | B12: Mercado | C12: SulAmérica Crédito ESG FIRF CP LP IS | D12: SulAmérica Investimentos | E12: =INDEX(Sheet1!C:C,MATCH('Ranking Quantitativo'!C12,Sheet1!B:B,0)) -> 33701828000126 | F12: 11 | G12: 46 | H12: 0.006 | I12: 0.92288914 | J12: 1.0033957 | K12: 1.0651462 | L12: 1.1452215 | M12: 0.001479306 | N12: 0.29654697 | O12: -6.8956248e-05 | P12: 3/4 | Q12: 73.727106 | R12: 81.678322 | S12: 67.307692 | T12: 23.269231 | U12: 69.38524
A13: 12 | B13: Mercado | C13: Bocom BBM Corporate Credit II FIF RF CP RL | D13: BOCOM BBM Investimentos | E13: =INDEX(Sheet1!C:C,MATCH('Ranking Quantitativo'!C13,Sheet1!B:B,0)) -> 49996302000150 | F13: 13 | G13: 31 | H13: 0.006 | I13: 0.97688368 | J13: 1.0135992 | K13: 1.0535864 | M13: 0.0025784676 | N13: 0.68050876 | O13: -0.00034064309 | P13: 2/3 | Q13: 76.31721 | R13: 56.468531 | S13: 75 | T13: 40.576923 | U13: 67.517569
A14: 13 | B14: Mercado | C14: BOCOM BBM Corporate Credit Plus FIF CIC MULT CP RL | D14: BOCOM BBM Investimentos | E14: =INDEX(Sheet1!C:C,MATCH('Ranking Quantitativo'!C14,Sheet1!B:B,0)) -> 34799129000123 | F14: 13 | G14: 121 | H14: 0.009 | I14: 1.0070401 | J14: 1.0440933 | K14: 1.0814699 | L14: 1.1212772 | M14: 0.0044325919 | N14: 1.2807941 | O14: -0.0020944009 | P14: 4/4 | Q14: 92.64652 | R14: 34.947552 | S14: 84.615385 | T14: 1.5384615 | U14: 67.504745
A15: 14 | B15: Mercado | C15: Root Capital Crédito HG Plus FIC de FIF Multimercado CP RL | D15: Root Capital | E15: =INDEX(Sheet1!C:C,MATCH('Ranking Quantitativo'!C15,Sheet1!B:B,0)) -> 42405028000159 | F15: 13 | G15: 60 | H15: 0.0104 | I15: 0.88847799 | J15: 1.0159979 | K15: 1.0706601 | L15: 1.1167846 | M15: 0.0019103322 | N15: 1.0792761 | O15: -0.00052497305 | P15: 3/4 | Q15: 74.817504 | R15: 59.414336 | S15: 82.692308 | T15: 3.0769231 | U15: 65.367615
A16: 15 | B16: Mercado | C16: Novus Crédito FIM CP LP | D16: Novus Crédito Gestão de Recursos Ltda. | E16: =INDEX(Sheet1!C:C,MATCH('Ranking Quantitativo'!C16,Sheet1!B:B,0)) -> 45443993000104 | F16: 13 | G16: 31 | H16: 0.007 | I16: 0.94790078 | J16: 0.99977507 | K16: 1.0552487 | L16: 1.1627683 | M16: 0.0024863877 | N16: -0.01042642 | O16: -0.0002475198 | P16: 2/4 | Q16: 74.87899 | R16: 58.924825 | S16: 63.461538 | T16: 30.576923 | U16: 64.176752
A17: 16 | B17: Mercado | C17: Occam Crédito Corporativo 30 FIC FIF RF CP LP RL | D17: Occam Investimentos | E17: =INDEX(Sheet1!C:C,MATCH('Ranking Quantitativo'!C17,Sheet1!B:B,0)) -> 47586648000155 | F17: 12 | G17: 31 | H17: 0.006 | I17: 0.91901461 | J17: 1.0076142 | K17: 1.0405801 | L17: 1.1129882 | M17: 0.002197676 | N17: 0.44745423 | O17: -0.00013011987 | P17: 3/4 | Q17: 62.788462 | R17: 66.145105 | S17: 73.076923 | T17: 40.576923 | U17: 63.464161
A18: 17 | B18: Mercado | C18: Safra Vitesse Classe de Investimento RF CP RL | D18: Safra Asset Management | E18: =INDEX(Sheet1!C:C,MATCH('Ranking Quantitativo'!C18,Sheet1!B:B,0)) -> 11447124000136 | F18: 3 | G18: 31 | H18: 0.005 | I18: 0.97990776 | J18: 1.0039217 | K18: 1.0118508 | L18: 1.0592284 | M18: 0.0014395365 | N18: 0.35177664 | P18: 3/4 | Q18: 44.561094 | R18: 91.272189 | S18: 69.230769 | T18: 52.884615 | U18: 62.005155
A19: 18 | B19: Mercado | C19: Principal Claritas FIF RF | D19: Principal Asset Management LTDA | E19: =INDEX(Sheet1!C:C,MATCH('Ranking Quantitativo'!C19,Sheet1!B:B,0)) -> 11447136000160 | F19: 11 | G19: 31 | H19: 0.005 | I19: 1.0165733 | J19: 1.0231728 | K19: 1.0202975 | L19: 1.0922149 | M19: 0.0031585152 | N19: 0.94583378 | O19: -0.00083181305 | P19: 4/4 | Q19: 61.784406 | R19: 50.708042 | S19: 80.769231 | T19: 52.884615 | U19: 61.922301
A20: 19 | B20: Mercado | C20: Safra Polaris Classe de Investimento RF CP RL | D20: Safra DTVM (*) | E20: =INDEX(Sheet1!C:C,MATCH('Ranking Quantitativo'!C20,Sheet1!B:B,0)) -> 30056825000199 | F20: 6 | G20: 16 | H20: 0.006 | I20: 0.95893193 | J20: 0.99789547 | K20: 1.022773 | L20: 1.0805906 | M20: 0.0018297902 | N20: -0.14736428 | P20: 2/4 | Q20: 50.238749 | R20: 79.733728 | S20: 61.538462 | T20: 65.384615 | U20: 61.387023
A21: 20 | B21: Mercado | C21: Safra Grand Vitesse FIRF CP | D21: SAFRA ASSET CTVM S.A. | E21: =INDEX(Sheet1!C:C,MATCH('Ranking Quantitativo'!C21,Sheet1!B:B,0)) -> 23714047000112 | F21: 10 | G21: 31 | H21: 0.0025 | I21: 0.98432676 | J21: 1.0068783 | K21: 1.0069363 | L21: 1.0603635 | M21: 0.0019899829 | N21: 0.44631575 | O21: -0.00023385031 | P21: 3/4 | Q21: 43.549843 | R21: 76.547203 | S21: 71.153846 | T21: 62.5 | U21: 59.214999
A22: 21 | B22: Mercado | C22: Compass Yield 30 FIF RF CP LP RL | D22: Compass Group Investimentos | E22: =INDEX(Sheet1!C:C,MATCH('Ranking Quantitativo'!C22,Sheet1!B:B,0)) -> 36318479000156 | F22: 11 | G22: 30 | H22: 0.006 | I22: 1.0198279 | J22: 0.99207863 | K22: 1.0656045 | L22: 1.1432249 | M22: 0.0056807037 | N22: -0.17700014 | O22: -0.0050710223 | P22: 3/4 | Q22: 77.132391 | R22: 23.758741 | S22: 59.615385 | T22: 58.461538 | U22: 58.418492
A23: 22 | B23: Mercado | C23: BTG Pactual Crédito Corporativo I FIF em Cotas de FIRF | D23: BTG Pactual Asset Management | E23: =INDEX(Sheet1!C:C,MATCH('Ranking Quantitativo'!C23,Sheet1!B:B,0)) -> 14171644000157 | F23: 11 | G23: 31 | H23: 0.005 | I23: 0.96033052 | J23: 0.98254252 | K23: 1.035441 | L23: 1.1576883 | M23: 0.0027795454 | N23: -0.80908807 | O23: -0.0014421602 | P23: 2/4 | Q23: 60.978545 | R23: 51.923077 | S23: 48.076923 | T23: 52.884615 | U23: 55.324961
A24: 23 | B24: Mercado | C24: Ibiuna Credit FIF CIC Multimercado CP RL | D24: Ibiuna Investimentos | E24: =INDEX(Sheet1!C:C,MATCH('Ranking Quantitativo'!C24,Sheet1!B:B,0)) -> 37310657000165 | F24: 12 | G24: 31 | H24: 0.0076 | I24: 0.9479869 | J24: 1.030095 | K24: 1.0417515 | L24: 1.0748777 | M24: 0.0056043317 | N24: 0.69362536 | O24: -0.0032790377 | P24: 3/4 | Q24: 66.63854 | R24: 25.769231 | S24: 76.923077 | T24: 26.346154 | U24: 54.448881
A25: 24 | B25: Mercado | C25: XP Corporate Light FIRF CP LP | D25: XP Asset Management | E25: =INDEX(Sheet1!C:C,MATCH('Ranking Quantitativo'!C25,Sheet1!B:B,0)) -> 11046179000134 | F25: 2 | G25: 7 | H25: 0.005 | I25: 0.94833783 | J25: 0.98302232 | K25: 1.0130693 | L25: 1.066472 | M25: 0.0010279062 | N25: -2.1307755 | P25: 2/4 | Q25: 39.51269 | R25: 97.04142 | S25: 7.6923077 | T25: 90.384615 | U25: 52.617988
A26: 25 | B26: Cliente | C26: JGP Crédito Advisory FIF Multimercado CP RL | D26: JGP GESTÃO DE CRÉDITO LTDA. | E26: =INDEX(Sheet1!C:C,MATCH('Ranking Quantitativo'!C26,Sheet1!B:B,0)) -> 28767162000179 | F26: 13 | G26: 46 | H26: 0.011 | I26: 0.87199043 | J26: 1.00246 | K26: 1.0721634 | L26: 1.1479757 | M26: 0.0076064925 | N26: 0.04546604 | O26: -0.0026436398 | P26: 3/4 | Q26: 73.959969 | R26: 19.72028 | S26: 65.384615 | T26: 5.1923077 | U26: 51.80821
A27: 26 | B27: Mercado | C27: Plural Crédito Corporativo II FIC de FIF RF CP LP RL | D27: Plural Investimentos | E27: =INDEX(Sheet1!C:C,MATCH('Ranking Quantitativo'!C27,Sheet1!B:B,0)) -> 18316558000146 | F27: 11 | G27: 31 | H27: 0.005 | I27: 0.95051564 | J27: 0.98659176 | K27: 1.0126041 | L27: 1.0820093 | M27: 0.0018030726 | N27: -0.95845103 | O27: -0.00032458588 | P27: 2/4 | Q27: 43.195317 | R27: 73.513986 | S27: 38.461538 | T27: 52.884615 | U27: 50.797158
A28: 27 | B28: Cliente | C28: Polo Crédito Corporativo Advisory FIC FIF RF CP LP RL | D28: Polo Capital | E28: =INDEX(Sheet1!C:C,MATCH('Ranking Quantitativo'!C28,Sheet1!B:B,0)) -> 31455879000190 | F28: 11 | G28: 31 | H28: 0.005 | I28: 0.7541109 | J28: 0.97286696 | K28: 1.0453429 | L28: 1.1144447 | M28: 0.0037790157 | N28: -0.92520398 | O28: -0.0012305929 | P28: 2/4 | Q28: 51.816457 | R28: 45.795455 | S28: 42.307692 | T28: 52.884615 | U28: 48.516269
A29: 28 | B29: Mercado | C29: Integral FIRF CP | D29: Integral Investimentos | E29: =INDEX(Sheet1!C:C,MATCH('Ranking Quantitativo'!C29,Sheet1!B:B,0)) -> 15174629000125 | F29: 10 | G29: 30 | H29: 0.0075 | I29: 0.89479791 | J29: 0.981936 | K29: 1.0106214 | L29: 1.0842766 | M29: 0.0030975766 | N29: -0.75101487 | O29: -0.00034163604 | P29: 2/4 | Q29: 37.25471 | R29: 62.115385 | S29: 50 | T29: 45.769231 | U29: 46.870389
A30: 29 | B30: Cliente | C30: Porto Seguro Ipê RF FIC FI CP LP | D30: Porto Investimentos | E30: =INDEX(Sheet1!C:C,MATCH('Ranking Quantitativo'!C30,Sheet1!B:B,0)) -> 35378376000119 | F30: 11 | G30: 30 | H30: 0.005 | I30: 0.83030927 | J30: 0.97629061 | K30: 1.0296785 | L30: 1.115647 | M30: 0.0021268134 | N30: -1.4380563 | O30: -0.0011280111 | P30: 2/4 | Q30: 45.477499 | R30: 58.706294 | S30: 21.153846 | T30: 70.769231 | U30: 46.44914
A31: 30 | B31: Mercado | C31: Augme 30 II CIC de CIRF CP LP RL | D31: Augme Capital | E31: =INDEX(Sheet1!C:C,MATCH('Ranking Quantitativo'!C31,Sheet1!B:B,0)) -> 52285852000176 | F31: 11 | G31: 31 | H31: 0.006 | I31: 0.80508327 | J31: 0.98670528 | K31: 1.0406337 | M31: 0.007604477 | N31: -0.22175691 | O31: -0.0023221546 | P31: 1/3 | Q31: 52.00157 | R31: 29.702797 | S31: 57.692308 | T31: 40.576923 | U31: 46.42256
A32: 31 | B32: Mercado | C32: Sparta Top FIC FIF RF CP LP - Resp Limitada | D32: Sparta Investimentos | E32: =INDEX(Sheet1!C:C,MATCH('Ranking Quantitativo'!C32,Sheet1!B:B,0)) -> 14188162000100 | F32: 6 | G32: 31 | H32: 0.003 | I32: 0.95362954 | J32: 0.96076638 | K32: 1.028873 | L32: 1.1239353 | M32: 0.0038982926 | N32: -1.2985932 | O32: -0.0021809494 | P32: 2/4 | Q32: 48.697671 | R32: 49.632867 | S32: 28.846154 | T32: 61.730769 | U32: 46.264477
A33: 32 | B33: Cliente | C33: Sparta Max Advisory FIC de FIF RF CP LP RL | D33: Sparta Investimentos | E33: =INDEX(Sheet1!C:C,MATCH('Ranking Quantitativo'!C33,Sheet1!B:B,0)) -> 32757330000112 | F33: 10 | G33: 31 | H33: 0.0035 | I33: 0.94630209 | J33: 0.95084131 | K33: 1.0395763 | L33: 1.1568513 | M33: 0.0052645791 | N33: -1.2047816 | O33: -0.0024009558 | P33: 2/4 | Q33: 50.871272 | R33: 41.59965 | S33: 32.692308 | T33: 60.192308 | U33: 45.849677
A34: 33 | B34: Mercado | C34: Western Asset Total Credit Plus FIF | D34: FRANKLIN TEMPLETON BRASIL LTDA. | E34: =INDEX(Sheet1!C:C,MATCH('Ranking Quantitativo'!C34,Sheet1!B:B,0)) -> 49984055000172 | F34: 11 | G34: 10 | H34: 0.0065 | I34: 0.92424354 | J34: 0.97851548 | K34: 1.0064495 | M34: 0.0020671094 | N34: -1.3405149 | O34: -0.00036899504 | P34: 1/3 | Q34: 34.114992 | R34: 65.935315 | S34: 25 | T34: 68.269231 | U34: 43.662498
A35: 34 | B35: Mercado | C35: AF Invest Geraes 30 FIRF CP | D35: AF Invest Investimentos | E35: =INDEX(Sheet1!C:C,MATCH('Ranking Quantitativo'!C35,Sheet1!B:B,0)) -> 29044189000104 | F35: 10 | G35: 31 | H35: 0.005 | I35: 0.74337488 | J35: 0.96118165 | K35: 1.0444994 | L35: 1.0966219 | M35: 0.0093705504 | N35: -0.53063587 | O35: -0.0030525598 | P35: 2/4 | Q35: 46.039377 | R35: 26.372378 | S35: 53.846154 | T35: 52.884615 | U35: 43.368506
A36: 35 | B36: Mercado | C36: Tríade CIC CLasses FIM CP Resp Limitada | D36: Paramis Investimentos | E36: =INDEX(Sheet1!C:C,MATCH('Ranking Quantitativo'!C36,Sheet1!B:B,0)) -> 54026669000181 | F36: 13 | G36: 30 | H36: 0.0066 | I36: 0.86673011 | J36: 0.97639139 | M36: 0.0027935003 | N36: -1.0896059 | O36: -0.0011184835 | P36: 0/2 | Q36: 41.923077 | R36: 46.713287 | S36: 36.538462 | T36: 50.384615 | U36: 42.88986
A37: 36 | B37: Mercado | C37: Inter Premium FIF RF CP LP RL | D37: Inter Asset Management | E37: =INDEX(Sheet1!C:C,MATCH('Ranking Quantitativo'!C37,Sheet1!B:B,0)) -> 27826059000190 | F37: 3 | G37: 15 | H37: 0.006 | I37: 0.85776955 | J37: 0.96919988 | K37: 1.0160277 | L37: 1.0655431 | M37: 0.0029961543 | N37: -1.3261805 | O37: -0.00040110057 | P37: 2/4 | Q37: 31.510989 | R37: 65.017483 | S37: 26.923077 | T37: 68.846154 | U37: 42.703546
A38: 37 | B38: Mercado | C38: Riza Lotus Plus Advisory FIF RF | D38: Riza Líquidos Gestora de Recursos | E38: =INDEX(Sheet1!C:C,MATCH('Ranking Quantitativo'!C38,Sheet1!B:B,0)) -> 43917493000131 | F38: 10 | G38: 11 | H38: 0.005 | I38: 0.95176388 | J38: 0.95195683 | K38: 1.0423084 | L38: 1.0569233 | M38: 0.0069089981 | N38: -0.89563835 | O38: -0.0063271517 | P38: 2/4 | Q38: 41.536499 | R38: 23.61014 | S38: 44.230769 | T38: 84.615385 | U38: 41.901652
A39: 38 | B39: Mercado | C39: Iridium Titan Advisory FIC em FIF RF CP RL | D39: Iridium Investimentos | E39: =INDEX(Sheet1!C:C,MATCH('Ranking Quantitativo'!C39,Sheet1!B:B,0)) -> 32756812000158 | F39: 11 | G39: 31 | H39: 0.006 | I39: 0.77323814 | J39: 0.96393559 | K39: 1.0439671 | L39: 1.0729822 | M39: 0.0049718171 | N39: -0.93468305 | O39: -0.0024993917 | P39: 2/4 | Q39: 43.15607 | R39: 36.765734 | S39: 40.384615 | T39: 40.576923 | U39: 40.746281
A40: 39 | B40: Cliente | C40: Arx Vinson Advisory FIC de FIF RF CP RL | D40: ARX Investimentos | E40: =INDEX(Sheet1!C:C,MATCH('Ranking Quantitativo'!C40,Sheet1!B:B,0)) -> 41888492000180 | F40: 3 | G40: 31 | H40: 0.005 | I40: 0.79245189 | J40: 0.94911336 | K40: 1.0371472 | L40: 1.0696855 | M40: 0.0047315143 | N40: -1.3884552 | O40: -0.000893358 | P40: 2/4 | Q40: 32.301151 | R40: 55.777972 | S40: 23.076923 | T40: 52.884615 | U40: 38.383857
...

Sheet Sheet1
B2: Fundo | C2: CNPJ
B3: Persevera Yield FIRF LP | C3: 51693641000100
B4: BNP Paribas Rubi FIF RF CP RL | C4: 21185984000100
B5: Daycoval Classic 30 FIRF CP | C5: 29250121000173
B6: SulAmérica Crédito Ativo FIRF CP LP | C6: 13823084000105
B7: BNP Paribas Match Plus 30 Advisory FIF RF CP LP RL | C7: 50098505000109
B8: Tivio Institucional 15 | C8: 04240128000183
B9: Bradesco Ultra II FIF - CIC RF CP LP - RL | C9: 55315627000123
B10: Mag High Grade Plus 30 FIF RF CP LP RL | C10: 50697486000137
B11: Vinland Crédito 10 FIC FIRF | C11: 53678015000170
B12: Atena Yield D30 FIC de FIF RF CP RL | C12: 31340838000158
B13: SulAmérica Crédito ESG FIRF CP LP IS | C13: 33701828000126
... B56: ARX Everest Advisory FIC de FIF RF CP RL | C56: 35789436000196

Sheet Fundos Cliente
A1: Ranking Cliente | B1: Ranking Geral | C1: Fundo | D1: Gestor | E1: Liquidez | F1: Ano % CDI | G1: 12M % CDI | H1: 24M % CDI | I1: 36M % CDI | J1: Vol 12M | K1: Sharpe 12M | L1: Max DD 12M | M1: Score Final | N1: Recomendação Quantitativa
A2: 1 | B2: 25 | C2: JGP Crédito Advisory FIF Multimercado CP RL | D2: JGP GESTÃO DE CRÉDITO LTDA. | E2: 46 | F2: 0.87199043 | G2: 1.00246 | H2: 1.0721634 | I2: 1.1479757 | J2: 0.0076064925 | K2: 0.04546604 | L2: -0.0026436398 | M2: 51.80821 | N2: Manter como melhor fundo do cliente na análise quantitativa; sem aumento relevante até Sharpe melhorar.
A3: 2 | B3: 27 | C3: Polo Crédito Corporativo Advisory FIC FIF RF CP LP RL | D3: Polo Capital | E3: 31 | F3: 0.7541109 | G3: 0.97286696 | H3: 1.0453429 | I3: 1.1144447 | J3: 0.0037790157 | K3: -0.92520398 | L3: -0.0012305929 | M3: 48.516269 | N3: Manter sob observação/sem novos aportes; 24–36M ainda ajudam, mas 12M ficou abaixo do CDI.
A4: 3 | B4: 29 | C4: Porto Seguro Ipê RF FIC FI CP LP | D4: Porto Investimentos | E4: 30 | F4: 0.83030927 | G4: 0.97629061 | H4: 1.0296785 | I4: 1.115647 | J4: 0.0021268134 | K4: -1.4380563 | L4: -0.0011280111 | M4: 46.44914 | N4: Manter sob observação/sem novos aportes; 24–36M ainda ajudam, mas 12M ficou abaixo do CDI.
A5: 4 | B5: 32 | C5: Sparta Max Advisory FIC de FIF RF CP LP RL | D5: Sparta Investimentos | E5: 31 | F5: 0.94630209 | G5: 0.95084131 | H5: 1.0395763 | I5: 1.1568513 | J5: 0.0052645791 | K5: -1.2047816 | L5: -0.0024009558 | M5: 45.849677 | N5: Manter sob observação/sem novos aportes; 24–36M ainda ajudam, mas 12M ficou abaixo do CDI.
A6: 5 | B6: 39 | C6: Arx Vinson Advisory FIC de FIF RF CP RL | D6: ARX Investimentos | E6: 31 | F6: 0.79245189 | G6: 0.94911336 | H6: 1.0371472 | I6: 1.0696855 | J6: 0.0047315143 | K6: -1.3884552 | L6: -0.000893358 | M6: 38.383857 | N6: Reavaliar manutenção; desempenho ajustado a risco inferior ao universo comparável.
A7: 6 | B7: 48 | C7: AZ Quest Altro Advisory FIC de FIF Multimercado CP | D7: AZ Quest MZK Investimentos | E7: 45 | F7: 0.46648353 | G7: 0.89943746 | H7: 1.0148355 | I7: 1.1835584 | J7: 0.0081035882 | K7: -1.6059331 | L7: -0.010210292 | M7: 19.886266 | N7: Congelar novos aportes e reduzir gradualmente; tese depende de recuperação dos eventos de crédito.
A8: 7 | B8: 50 | C8: SPX Seahawk Advisory FIC FIRF CP LP | D8: SPX Capital | E8: 31 | F8: 0.58599259 | G8: 0.87834516 | H8: 0.99947267 | I8: 1.0961954 | J8: 0.0066295613 | K8: -2.3806562 | L8: -0.0043796553 | M8: 16.906076 | N8: Reduzir/zerar de forma escalonada; pior combinação de 12M CDI, Sharpe e ranking.

Sheet Base Tratada
A1: Grupo | B1: Ranking Geral | C1: Fundo | D1: Gestor | E1: Administrador | F1: Risco XP | G1: Classificação XP | H1: Aplicação Inicial | I1: Cotização | J1: Liquidação | K1: Liquidez total (Cotização + Liquidação) em número (aproximação para filtros) | L1: Taxa de Administração | M1: Benchmark | N1: Data de Início | O1: Mês | P1: Ano | Q1: 12 Meses | R1: 24 Meses (Anualizado) | S1: 36 Meses (Anualizado) | T1: Ano (CDI) | U1: 12 Meses (CDI) | V1: 24 Meses (CDI) | W1: 36 Meses (CDI) | X1: Volatilidade 12 meses | Y1: Sharpe 12 meses | Z1: Máx Drawdown 12 meses | AA1: Score Retorno Relativo | AB1: Score Risco | AC1: Score Consistência | AD1: Score Liquidez/Custo | AE1: Score Quantitativo | AF1: Janelas > CDI | AG1: Janelas avaliadas
A2: Mercado | B2: 1 | C2: Persevera Yield FIRF LP | D2: Persevera Asset Management | E2: BTG Pactual Serviços Financeiros | F2: 10 | G2: Crédito High Grade | H2: 500 | I2: D+14 (corridos) | J2: D+1 (útil) | K2: 15 | L2: 0.007 | M2: CDI | N2: 45196 | O2: 0.00041732049 | P2: 0.0018973443 | Q2: 0.0087140412 | R2: 0.0066461609 | S2: - | T2: 1.0556068 | U2: 1.0589278 | V2: 1.0579844 | W2: - | X2: 0.0013838478 | Y2: 5.4687897 | Z2: - | AA2: 93.877551 | AB2: 85.798817 | AC2: 100 | AD2: 58.846154 | AE2: 89.579217 | AF2: 3 | AG2: 3
A3: Mercado | B3: 13 | C3: BOCOM BBM Corporate Credit Plus FIF CIC MULT CP RL | D3: BOCOM BBM Investimentos | E3: BEM DTVM | F3: 13 | G3: Crédito High Grade | H3: 1000 | I3: D+120 (corridos) | J3: D+1 (útil) | K3: 121 | L3: 0.009 | M3: CDI | N3: 43826 | O3: -0.00042488892 | P3: 0.00024021292 | Q3: 0.0065203675 | R3: 0.0093270266 | S3: 0.013669804 | T3: 1.0070401 | U3: 1.0440933 | V3: 1.0814699 | W3: 1.1212772 | X3: 0.0044325919 | Y3: 1.2807941 | Z3: -0.0020944009 | AA3: 92.64652 | AB3: 34.947552 | AC3: 84.615385 | AD3: 1.5384615 | AE3: 67.504745 | AF3: 4 | AG3: 4
A4: Mercado | B4: 10 | C4: Atena Yield D30 FIC de FIF RF CP RL | D4: Atena Capital | E4: BTG Pactual Serviços Financeiros | F4: 11 | G4: Crédito High Grade | H4: 1000 | I4: D+29 (corridos) | J4: D+1 (útil) | K4: 30 | L4: 0.0085 | M4: CDI | N4: 43444 | O4: -0.00033932113 | P4: 0.00083025849 | Q4: 0.0058221448 | R4: 0.0041103089 | S4: 0.0076182757 | T4: 1.024333 | U4: 1.0393716 | V4: 1.0358203 | W4: 1.0672421 | X4: 0.0012778347 | Y4: 3.9620969 | Z4: - | AA4: 68.297357 | AB4: 78.254438 | AC4: 96.153846 | AD4: 42.692308 | AE4: 73.79742 | AF4: 4 | AG4: 4
A5: Mercado | B5: 2 | C5: BNP Paribas Rubi FIF RF CP RL | D5: BNP Paribas Asset Management | E5: BNP Paribas | F5: 4 | G5: Crédito High Grade | H5: 500 | I5: D+9 (corridos) | J5: D+1 (útil) | K5: 10 | L5: 0.004 | M5: CDI | N5: 42003 | O5: -0.00051186895 | P5: 4.9830661e-05 | Q5: 0.0050414118 | R5: 0.0062298395 | S5: 0.0097467285 | T5: 1.0014604 | U5: 1.034092 | V5: 1.0543423 | W5: 1.0861845 | X5: 0.00080229319 | Y5: 5.465681 | Z5: - | AA5: 79.17517 | AB5: 96.153846 | AC5: 98.076923 | AD5: 93.653846 | AE5: 88.648057 | AF5: 4 | AG5: 4
A6: Mercado | B6: 4 | C6: SulAmérica Crédito Ativo FIRF CP LP | D6: SulAmérica Investimentos | E6: SulAmérica Investimentos | F6: 11 | G6: Crédito High Grade | H6: 1000 | I6: D+29 (corridos) | J6: D+1 (útil) | K6: 30 | L6: 0.006 | M6: CDI | N6: 40994 | O6: -0.0017816576 | P6: -0.00047581464 | Q6: 0.005010271 | R6: 0.0082977014 | S6: 0.015844149 | T6: 0.98605497 | U6: 1.0338814 | V6: 1.072446 | W6: 1.1408274 | X6: 0.0028243912 | Y6: 1.5442974 | Z6: -0.00010925469 | AA6: 89.489796 | AB6: 65.305944 | AC6: 88.461538 | AD6: 58.461538 | AE6: 80.135356 | AF6: 3 | AG6: 4
A7: Mercado | B7: 8 | C7: Mag High Grade Plus 30 FIF RF CP LP RL | D7: Mongeral Aegon Investimentos | E7: BNY Mellon Serviços Financeiros | F7: 11 | G7: Crédito High Grade | H7: 1000 | I7: D+30 (corridos) | J7: D+1 (útil) | K7: 31 | L7: 0.0064 | M7: CDI | N7: 45070 | O7: -0.00037120416 | P7: 0.00031291667 | Q7: 0.0046098831 | R7: 0.0041816563 | S7: - | T7: 1.0091709 | U7: 1.0311738 | V7: 1.0364432 | W7: - | X7: 0.0017909506 | Y7: 2.2400288 | Z7: - | AA7: 75.983615 | AB7: 71.597633 | AC7: 92.307692 | AD7: 34.807692 | AE7: 74.034343 | AF7: 3 | AG7: 3
A8: Mercado | B8: 23 | C8: Ibiuna Credit FIF CIC Multimercado CP RL | D8: Ibiuna Investimentos | E8: BEM DTVM | F8: 12 | G8: Crédito High Grade | H8: 1000 | I8: D+30 (corridos) | J8: D+1 (útil) | K8: 31 | L8: 0.0076 | M8: CDI | N8: 44043 | O8: -0.002282025 | P8: -0.0017747253 | Q8: 0.0044503459 | R8: 0.0047894637 | S8: 0.0084771685 | T8: 0.9479869 | U8: 1.030095 | V8: 1.0417515 | W8: 1.0748777 | X8: 0.0056043317 | Y8: 0.69362536 | Z8: -0.0032790377 | AA8: 66.63854 | AB8: 25.769231 | AC8: 76.923077 | AD8: 26.346154 | AE8: 54.448881 | AF8: 3 | AG8: 4
A9: Mercado | B9: 5 | C9: BNP Paribas Match Plus 30 Advisory FIF RF CP LP RL | D9: BNP Paribas Asset Management | E9: BNP Paribas | F9: 11 | G9: Crédito High Grade | H9: 500 | I9: D+29 (corridos) | J9: D+1 (útil) | K9: 30 | L9: 0.0065 | M9: CDI | N9: 45022 | O9: -0.00077250081 | P9: -0.00030550116 | Q9: 0.0038456713 | R9: 0.0047822986 | S9: - | T9: 0.99104647 | U9: 1.0260059 | V9: 1.0416889 | W9: - | X9: 0.00090431071 | Y9: 3.7010515 | Z9: - | AA9: 77.811028 | AB9: 80.91716 | AC9: 94.230769 | AD9: 51.538462 | AE9: 79.244253 | AF9: 2 | AG9: 3
A10: Mercado | B10: 3 | C10: Daycoval Classic 30 FIRF CP | D10: Daycoval Asset Management | E10: Banco Daycoval | F10: 3 | G10: Crédito High Grade | H10: 500 | I10: D+29 (corridos) | J10: D+1 (útil) | K10: 30 | L10: 0.004 | M10: CDI | N10: 43283 | O10: -0.0016463779 | P10: -0.00049840457 | Q10: 0.0035099268 | R10: 0.0059961602 | S10: 0.01140056 | T10: 0.98539291 | U10: 1.0237355 | V10: 1.0522985 | W10: 1.10095 | X10: 0.0018143026 | Y10: 1.6846203 | Z10: -6.6220064e-05 | AA10: 75.624673 | AB10: 89.204545 | AC10: 90.384615 | AD10: 76.923077 | AE10: 82.10147 | AF10: 3 | AG10: 4
A11: Mercado | B11: 18 | C11: Principal Claritas FIF RF | D11: Principal Asset Management LTDA | E11: BTG Pactual Serviços Financeiros | F11: 11 | G11: Crédito High Grade | H11: 1000 | I11: D+30 (corridos) | J11: D+1 (útil) | K11: 31 | L11: 0.005 | M11: - | N11: 40302 | O11: -0.00033340664 | P11: 0.00056549231 | Q11: 0.0034267211 | R11: 0.0023309302 | S11: 0.010422728 | T11: 1.0165733 | U11: 1.0231728 | V11: 1.0202975 | W11: 1.0922149 | X11: 0.0031585152 | Y11: 0.94583378 | Z11: -0.00083181305 | AA11: 61.784406 | AB11: 50.708042 | AC11: 80.769231 | AD11: 52.884615 | AE11: 61.922301 | AF11: 4 | AG11: 4
A12: Mercado | B12: 7 | C12: Bradesco Ultra II FIF - CIC RF CP LP - RL | D12: Bradesco S.A. | E12: Banco Bradesco | F12: 11 | G12: Crédito High Grade | H12: 1000 | I12: D+30 (corridos) | J12: D+1 (útil) | K12: 31 | L12: 0.006 | M12: CDI | N12: 45471 | O12: -0.0025934239 | P12: -0.0016196052 | Q12: 0.0033317297 | R12: - | S12: - | T12: 0.95253311 | U12: 1.0225305 | V12: - | W12: - | X12: 0.0019740415 | Y12: 1.4700027 | Z12: -4.1677604e-05 | AA12: 76.730769 | AB12: 77.211538 | AC12: 86.538462 | AD12: 40.576923 | AE12: 75.197115 | AF12: 1 | AG12: 2
A13: Mercado | B13: 6 | C13: Tivio Institucional 15 | D13: Tivio Capital | E13: BEM DTVM | F13: 11 | G13: Crédito High Grade | H13: 3000 | I13: D+15 (corridos) | J13: D+1 (útil) | K13: 16 | L13: 0.005 | M13: CDI | N13: 36983 | O13: -0.0030365265 | P13: -0.002667372 | Q13: 0.0027416809 | R13: 0.0089842206 | S13: 0.016836643 | T13: 0.92182548 | U13: 1.0185403 | V13: 1.0784637 | W13: 1.1497749 | X13: 0.0028298313 | Y13: 0.84490065 | Z13: -0.00013747754 | AA13: 82.579147 | AB13: 62.84965 | AC13: 78.846154 | AD13: 77.692308 | AE13: 76.41149 | AF13: 3 | AG13: 4
A14: Mercado | B14: 14 | C14: Root Capital Crédito HG Plus FIC de FIF Multimercado CP RL | D14: Root Capital | E14: BNY Mellon Serviços Financeiros | F14: 13 | G14: Crédito High Grade | H14: 5000 | I14: D+59 (corridos) | J14: D+1 (útil) | K14: 60 | L14: 0.0104 | M14: CDI | N14: 44560 | O14: -0.003298409 | P14: -0.003805213 | Q14: 0.002365719 | R14: 0.0080938771 | S14: 0.013169008 | T14: 0.88847799 | U14: 1.0159979 | V14: 1.0706601 | W14: 1.1167846 | X14: 0.0019103322 | Y14: 1.0792761 | Z14: -0.00052497305 | AA14: 74.817504 | AB14: 59.414336 | AC14: 82.692308 | AD14: 3.0769231 | AE14: 65.367615 | AF14: 3 | AG14: 4
A15: Mercado | B15: 12 | C15: Bocom BBM Corporate Credit II FIF RF CP RL | D15: BOCOM BBM Investimentos | E15: BEM DTVM | F15: 13 | G15: Crédito High Grade | H15: 100 | I15: D+30 (corridos) | J15: D+1 (útil) | K15: 31 | L15: 0.006 | M15: CDI | N15: 45026 | O15: -0.0010185865 | P15: -0.00078874567 | Q15: 0.0020110076 | R15: 0.0061434186 | S15: - | T15: 0.97688368 | U15: 1.0135992 | V15: 1.0535864 | W15: - | X15: 0.0025784676 | Y15: 0.68050876 | Z15: -0.00034064309 | AA15: 76.31721 | AB15: 56.468531 | AC15: 75 | AD15: 40.576923 | AE15: 67.517569 | AF15: 2 | AG15: 3
A16: Mercado | B16: 16 | C16: Occam Crédito Corporativo 30 FIC FIF RF CP LP RL | D16: Occam Investimentos | E16: BNY Mellon Serviços Financeiros | F16: 12 | G16: Crédito High Grade | H16: 500 | I16: D+30 (corridos) | J16: D+1 (útil) | K16: 31 | L16: 0.006 | M16: CDI | N16: 44923 | O16: -0.0030706637 | P16: -0.0027632808 | Q16: 0.0011259582 | R16: 0.0046553685 | S16: 0.012745499 | T16: 0.91901461 | U16: 1.0076142 | V16: 1.0405801 | W16: 1.1129882 | X16: 0.002197676 | Y16: 0.44745423 | Z16: -0.00013011987 | AA16: 62.788462 | AB16: 66.145105 | AC16: 73.076923 | AD16: 40.576923 | AE16: 63.464161 | AF16: 3 | AG16: 4
A17: Mercado | B17: 20 | C17: Safra Grand Vitesse FIRF CP | D17: SAFRA ASSET CTVM S.A. | E17: Safra Asset Management | F17: 10 | G17: Crédito High Grade | H17: 1000 | I17: D+30 (corridos) | J17: D+1 (útil) | K17: 31 | L17: 0.0025 | M17: CDI | N17: 43342 | O17: -0.0019583862 | P17: -0.00053478261 | Q17: 0.0010171373 | R17: 0.00079709918 | S17: 0.0068434622 | T17: 0.98432676 | U17: 1.0068783 | V17: 1.0069363 | W17: 1.0603635 | X17: 0.0019899829 | Y17: 0.44631575 | Z17: -0.00023385031 | AA17: 43.549843 | AB17: 76.547203 | AC17: 71.153846 | AD17: 62.5 | AE17: 59.214999 | AF17: 3 | AG17: 4
A18: Mercado | B18: 17 | C18: Safra Vitesse Classe de Investimento RF CP RL | D18: Safra Asset Management | E18: Safra Asset Management | F18: 3 | G18: Crédito High Grade | H18: 1000 | I18: D+30 (corridos) | J18: D+1 (útil) | K18: 31 | L18: 0.005 | M18: CDI | N18: 40771 | O18: -0.0013114369 | P18: -0.00068556188 | Q18: 0.00057993295 | R18: 0.0013615067 | S18: 0.0067155048 | T18: 0.97990776 | U18: 1.0039217 | V18: 1.0118508 | W18: 1.0592284 | X18: 0.0014395365 | Y18: 0.35177664 | Z18: - | AA18: 44.561094 | AB18: 91.272189 | AC18: 69.230769 | AD18: 52.884615 | AE18: 62.005155 | AF18: 3 | AG18: 4
A19: Mercado | B19: 11 | C19: SulAmérica Crédito ESG FIRF CP LP IS | D19: SulAmérica Investimentos | E19: SulAmérica Investimentos | F19: 11 | G19: Crédito High Grade | H19: 1000 | I19: D+45 (corridos) | J19: D+1 (útil) | K19: 46 | L19: 0.006 | M19: CDI | N19: 44172 | O19: -0.002616413 | P19: -0.0026310792 | Q19: 0.00050214797 | R19: 0.0074643462 | S19: 0.016331773 | T19: 0.92288914 | U19: 1.0033957 | V19: 1.0651462 | W19: 1.1452215 | X19: 0.001479306 | Y19: 0.29654697 | Z19: -6.8956248e-05 | AA19: 73.727106 | AB19: 81.678322 | AC19: 67.307692 | AD19: 23.269231 | AE19: 69.38524 | AF19: 3 | AG19: 4
A20: Mercado | B20: 15 | C20: Novus Crédito FIM CP LP | D20: Novus Crédito Gestão de Recursos Ltda. | E20: BTG Pactual Serviços Financeiros | F20: 13 | G20: Crédito High Grade | H20: 1000 | I20: D+30 (corridos) | J20: D+1 (útil) | K20: 31 | L20: 0.007 | M20: CDI | N20: 44819 | O20: -0.0017979314 | P20: -0.0017776635 | Q20: -3.3262238e-05 | R20: 0.0063334646 | S20: 0.018274976 | T20: 0.94790078 | U20: 0.99977507 | V20: 1.0552487 | W20: 1.1627683 | X20: 0.0024863877 | Y20: -0.01042642 | Z20: -0.0002475198 | AA20: 74.87899 | AB20: 58.924825 | AC20: 63.461538 | AD20: 30.576923 | AE20: 64.176752 | AF20: 2 | AG20: 4
A21: Mercado | B21: 19 | C21: Safra Polaris Classe de Investimento RF CP RL | D21: Safra DTVM (*) | E21: Safra Asset Management | F21: 6 | G21: Crédito High Grade | H21: 1000 | I21: D+15 (corridos) | J21: D+1 (útil) | K21: 16 | L21: 0.006 | M21: CDI | N21: 43671 | O21: -0.0015195374 | P21: -0.0014012727 | Q21: -0.00031121136 | R21: 0.0026148838 | S21: 0.0091189736 | T21: 0.95893193 | U21: 0.99789547 | V21: 1.022773 | W21: 1.0805906 | X21: 0.0018297902 | Y21: -0.14736428 | Z21: - | AA21: 50.238749 | AB21: 79.733728 | AC21: 61.538462 | AD21: 65.384615 | AE21: 61.387023 | AF21: 2 | AG21: 4
A22: Mercado | B22: 9 | C22: Vinland Crédito 10 FIC FIRF | D22: Vinland Capital Management | E22: BTG Pactual Serviços Financeiros | F22: 10 | G22: Crédito High Grade | H22: 1000 | I22: D+9 (corridos) | J22: D+1 (útil) | K22: 10 | L22: 0.005 | M22: CDI | N22: 45321 | O22: -0.0018205297 | P22: -0.001193523 | Q22: -0.00088364034 | R22: 0.0077452252 | S22: - | T22: 0.9650206 | U22: 0.99402448 | V22: 1.067606 | W22: - | X22: 0.0016284689 | Y22: -0.47235098 | Z22: -0.00014785599 | AA22: 73.8177 | AB22: 83.40035 | AC22: 55.769231 | AD22: 87.5 | AE22: 73.971899 | AF22: 1 | AG22: 3
A23: Mercado | B23: 21 | C23: Compass Yield 30 FIF RF CP LP RL | D23: Compass Group Investimentos | E23: BTG Pactual Serviços Financeiros | F23: 11 | G23: Crédito High Grade | H23: 500 | I23: D+29 (corridos) | J23: D+1 (útil) | K23: 30 | L23: 0.006 | M23: CDI | N23: 43971 | O23: -0.0010301241 | P23: 0.00067654321 | Q23: -0.001171386 | R23: 0.0075166904 | S23: 0.016110251 | T23: 1.0198279 | U23: 0.99207863 | V23: 1.0656045 | W23: 1.1432249 | X23: 0.0056807037 | Y23: -0.17700014 | Z23: -0.0050710223 | AA23: 77.132391 | AB23: 23.758741 | AC23: 59.615385 | AD23: 58.461538 | AE23: 58.418492 | AF23: 3 | AG23: 4
A24: Mercado | B24: 30 | C24: Augme 30 II CIC de CIRF CP LP RL | D24: Augme Capital | E24: BNY Mellon Serviços Financeiros | F24: 11 | G24: Crédito High Grade | H24: 500 | I24: D+30 (corridos) | J24: D+1 (útil) | K24: 31 | L24: 0.006 | M24: CDI | N24: 45197 | O24: -0.0054506902 | P24: -0.0066507021 | Q24: -0.0019659787 | R24: 0.0046614994 | S24: - | T24: 0.80508327 | U24: 0.98670528 | V24: 1.0406337 | W24: - | X24: 0.007604477 | Y24: -0.22175691 | Z24: -0.0023221546 | AA24: 52.00157 | AB24: 29.702797 | AC24: 57.692308 | AD24: 40.576923 | AE24: 46.42256 | AF24: 1 | AG24: 3
A25: Mercado | B25: 26 | C25: Plural Crédito Corporativo II FIC de FIF RF CP LP RL | D25: Plural Investimentos | E25: Intrag DTVM | F25: 11 | G25: Crédito High Grade | H25: 3000 | I25: D+30 (corridos) | J25: D+1 (útil) | K25: 31 | L25: 0.005 | M25: CDI | N25: 41506 | O25: -0.001610153 | P25: -0.0016884426 | Q25: -0.0019827653 | R25: 0.0014479961 | S25: 0.0092782463 | T25: 0.95051564 | U25: 0.98659176 | V25: 1.0126041 | W25: 1.0820093 | X25: 0.0018030726 | Y25: -0.95845103 | Z25: -0.00032458588 | AA25: 43.195317 | AB25: 73.513986 | AC25: 38.461538 | AD25: 52.884615 | AE25: 50.797158 | AF25: 2 | AG25: 4
A26: Mercado | B26: 24 | C26: XP Corporate Light FIRF CP LP | D26: XP Asset Management | E26: BNY Mellon Serviços Financeiros | F26: 2 | G26: Crédito High Grade | H26: 100 | I26: D+6 (corridos) | J26: D+1 (útil) | K26: 7 | L26: 0.005 | M26: CDI | N26: 40120 | O26: -0.0018194778 | P26: -0.0017627511 | Q26: -0.0025106025 | R26: 0.001501408 | S26: 0.0075315799 | T26: 0.94833783 | U26: 0.98302232 | V26: 1.0130693 | W26: 1.066472 | X26: 0.0010279062 | Y26: -2.1307755 | Z26: - | AA26: 39.51269 | AB26: 97.04142 | AC26: 7.6923077 | AD26: 90.384615 | AE26: 52.617988 | AF26: 2 | AG26: 4
A27: Mercado | B27: 22 | C27: BTG Pactual Crédito Corporativo I FIF em Cotas de FIRF | D27: BTG Pactual Asset Management | E27: BTG Pactual Serviços Financeiros | F27: 11 | G27: Crédito High Grade | H27: 5000 | I27: D+30 (corridos) | J27: D+1 (útil) | K27: 31 | L27: 0.005 | M27: CDI | N27: 40899 | O27: -0.001988836 | P27: -0.0013535517 | Q27: -0.002581554 | R27: 0.0040668629 | S27: 0.017713039 | T27: 0.96033052 | U27: 0.98254252 | V27: 1.035441 | W27: 1.1576883 | X27: 0.0027795454 | Y27: -0.80908807 | Z27: -0.0014421602 | AA27: 60.978545 | AB27: 51.923077 | AC27: 48.076923 | AD27: 52.884615 | AE27: 55.324961 | AF27: 2 | AG27: 4
A28: Mercado | B28: 28 | C28: Integral FIRF CP | D28: Integral Investimentos | E28: BTG Pactual Serviços Financeiros | F28: 10 | G28: Crédito High Grade | H28: 1000 | I28: D+29 (corridos) | J28: D+1 (útil) | K28: 30 | L28: 0.0075 | M28: CDI | N28: 41023 | O28: -0.0039827049 | P28: -0.0035895727 | Q28: -0.0026712444 | R28: 0.0012203408 | S28: 0.0095326982 | T28: 0.89479791 | U28: 0.981936 | V28: 1.0106214 | W28: 1.0842766 | X28: 0.0030975766 | Y28: -0.75101487 | Z28: -0.00034163604 | AA28: 37.25471 | AB28: 62.115385 | AC28: 50 | AD28: 45.769231 | AE28: 46.870389 | AF28: 2 | AG28: 4
A29: Mercado | B29: 33 | C29: Western Asset Total Credit Plus FIF | D29: FRANKLIN TEMPLETON BRASIL LTDA. | E29: BNP Paribas | F29: 11 | G29: Crédito High Grade | H29: 500 | I29: D+9 (corridos) | J29: D+1 (útil) | K29: 10 | L29: 0.0065 | M29: CDI | N29: 45133 | O29: -0.0020009481 | P29: -0.002584866 | Q29: -0.0031770594 | R29: 0.00074117425 | S29: - | T29: 0.92424354 | U29: 0.97851548 | V29: 1.0064495 | W29: - | X29: 0.0020671094 | Y29: -1.3405149 | Z29: -0.00036899504 | AA29: 34.114992 | AB29: 65.935315 | AC29: 25 | AD29: 68.269231 | AE29: 43.662498 | AF29: 1 | AG29: 3
A30: Mercado | B30: 35 | C30: Tríade CIC CLasses FIM CP Resp Limitada | D30: Paramis Investimentos | E30: BTG Pactual Serviços Financeiros | F30: 13 | G30: Crédito High Grade | H30: 500 | I30: D+29 (corridos) | J30: D+1 (útil) | K30: 30 | L30: 0.0066 | M30: CDI | N30: 45415 | O30: -0.002026972 | P30: -0.0045472665 | Q30: -0.0034911623 | R30: - | S30: - | T30: 0.86673011 | U30: 0.97639139 | V30: - | W30: - | X30: 0.0027935003 | Y30: -1.0896059 | Z30: -0.0011184835 | AA30: 41.923077 | AB30: 46.713287 | AC30: 36.538462 | AD30: 50.384615 | AE30: 42.88986 | AF30: 0 | AG30: 2
A31: Cliente | B31: 29 | C31: Porto Seguro Ipê RF FIC FI CP LP | D31: Porto Investimentos | E31: Intrag DTVM | F31: 11 | G31: Crédito High Grade | H31: 3000 | I31: D+29 (corridos) | J31: D+1 (útil) | K31: 30 | L31: 0.005 | M31: CDI | N31: 43798 | O31: -0.0038970628 | P31: -0.0057899724 | Q31: -0.0035060649 | R31: 0.0034066136 | S31: 0.013042135 | T31: 0.83030927 | U31: 0.97629061 | V31: 1.0296785 | W31: 1.115647 | X31: 0.0021268134 | Y31: -1.4380563 | Z31: -0.0011280111 | AA31: 45.477499 | AB31: 58.706294 | AC31: 21.153846 | AD31: 70.769231 | AE31: 46.44914 | AF31: 2 | AG31: 4
A32: Cliente | B32: 27 | C32: Polo Crédito Corporativo Advisory FIC FIF RF CP LP RL | D32: Polo Capital | E32: BNY Mellon Serviços Financeiros | F32: 11 | G32: Crédito High Grade | H32: 500 | I32: D+30 (corridos) | J32: D+1 (útil) | K32: 31 | L32: 0.005 | M32: CDI | N32: 43395 | O32: -0.0050501323 | P32: -0.0083899167 | Q32: -0.0040123429 | R32: 0.0052005101 | S32: 0.012908021 | T32: 0.7541109 | U32: 0.97286696 | V32: 1.0453429 | W32: 1.1144447 | X32: 0.0037790157 | Y32: -0.92520398 | Z32: -0.0012305929 | AA32: 51.816457 | AB32: 45.795455 | AC32: 42.307692 | AD32: 52.884615 | AE32: 48.516269 | AF32: 2 | AG32: 4
A33: Mercado | B33: 36 | C33: Inter Premium FIF RF CP LP RL | D33: Inter Asset Management | E33: Banco Inter DTVM | F33: 3 | G33: Crédito High Grade | H33: 500 | I33: D+14 (corridos) | J33: D+1 (útil) | K33: 15 | L33: 0.006 | M33: CDI | N33: 43039 | O33: -0.0019419147 | P33: -0.0048530073 | Q33: -0.0045546195 | R33: 0.0018409905 | S33: 0.0074269962 | T33: 0.85776955 | U33: 0.96919988 | V33: 1.0160277 | W33: 1.0655431 | X33: 0.0029961543 | Y33: -1.3261805 | Z33: -0.00040110057 | AA33: 31.510989 | AB33: 65.017483 | AC33: 26.923077 | AD33: 68.846154 | AE33: 42.703546 | AF33: 2 | AG33: 4
A34: Mercado | B34: 38 | C34: Iridium Titan Advisory FIC em FIF RF CP RL | D34: Iridium Investimentos | E34: BNY Mellon Serviços Financeiros | F34: 11 | G34: Crédito High Grade | H34: 100 | I34: D+30 (corridos) | J34: D+1 (útil) | K34: 31 | L34: 0.006 | M34: CDI | N34: 43591 | O34: -0.0054371745 | P34: -0.0077372813 | Q34: -0.0053330848 | R34: 0.0050430611 | S34: 0.0082640718 | T34: 0.77323814 | U34: 0.96393559 | V34: 1.0439671 | W34: 1.0729822 | X34: 0.0049718171 | Y34: -0.93468305 | Z34: -0.0024993917 | AA34: 43.15607 | AB34: 36.765734 | AC34: 40.384615 | AD34: 40.576923 | AE34: 40.746281 | AF34: 2 | AG34: 4
A35: Mercado | B35: 34 | C35: AF Invest Geraes 30 FIRF CP | D35: AF Invest Investimentos | E35: BTG Pactual Serviços Financeiros | F35: 10 | G35: Crédito High Grade | H35: 500 | I35: D+30 (corridos) | J35: D+1 (útil) | K35: 31 | L35: 0.005 | M35: CDI | N35: 43187 | O35: -0.009904218 | P35: -0.0087562374 | Q35: -0.0057403275 | R35: 0.0051039812 | S35: 0.010916266 | T35: 0.74337488 | U35: 0.96118165 | V35: 1.0444994 | W35: 1.0966219 | X35: 0.0093705504 | Y35: -0.53063587 | Z35: -0.0030525598 | AA35: 46.039377 | AB35: 26.372378 | AC35: 53.846154 | AD35: 52.884615 | AE35: 43.368506 | AF35: 2 | AG35: 4
A36: Mercado | B36: 31 | C36: Sparta Top FIC FIF RF CP LP - Resp Limitada | D36: Sparta Investimentos | E36: BNY Mellon Serviços Financeiros | F36: 6 | G36: Crédito High Grade | H36: 1000 | I36: D+30 (corridos) | J36: D+1 (útil) | K36: 31 | L36: 0.003 | M36: CDI | N36: 40946 | O36: -0.0014320515 | P36: -0.001582194 | Q36: -0.0058017363 | R36: 0.0033142915 | S36: 0.013965904 | T36: 0.95362954 | U36: 0.96076638 | V36: 1.028873 | W36: 1.1239353 | X36: 0.0038982926 | Y36: -1.2985932 | Z36: -0.0021809494 | AA36: 48.697671 | AB36: 49.632867 | AC36: 28.846154 | AD36: 61.730769 | AE36: 46.264477 | AF36: 2 | AG36: 4
A37: Mercado | B37: 40 | C37: Augme 30 Advisory CIC RF CP LP RL | D37: Augme Capital | E37: BTG Pactual Serviços Financeiros | F37: 11 | G37: Crédito High Grade | H37: 500 | I37: D+30 (corridos) | J37: D+1 (útil) | K37: 31 | L37: 0.006 | M37: CDI | N37: 43612 | O37: -0.0055127727 | P37: -0.0070677191 | Q37: -0.0058939347 | R37: 0.0025535479 | S37: 0.012538702 | T37: 0.79286146 | U37: 0.9601429 | V37: 1.0222382 | W37: 1.1111354 | X37: 0.0079160025 | Y37: -0.64672076 | Z37: -0.0045086538 | AA37: 36.696102 | AB37: 17.631119 | AC37: 51.923077 | AD37: 40.576923 | AE37: 35.363333 | AF37: 2 | AG37: 4
A38: Mercado | B38: 37 | C38: Riza Lotus Plus Advisory FIF RF | D38: Riza Líquidos Gestora de Recursos | E38: BTG Pactual Serviços Financeiros | F38: 10 | G38: Crédito High Grade | H38: 500 | I38: D+10 (corridos) | J38: D+1 (útil) | K38: 11 | L38: 0.005 | M38: CDI | N38: 44498 | O38: -0.0010987238 | P38: -0.001645852 | Q38: -0.0071044635 | R38: 0.004853213 | S38: 0.0064555756 | T38: 0.95176388 | U38: 0.95195683 | V38: 1.0423084 | W38: 1.0569233 | X38: 0.0069089981 | Y38: -0.89563835 | Z38: -0.0063271517 | AA38: 41.536499 | AB38: 23.61014 | AC38: 44.230769 | AD38: 84.615385 | AE38: 41.901652 | AF38: 2 | AG38: 4
A39: Mercado | B39: 41 | C39: XP Corporate Top CP FIF FIRF LP RL | D39: XP Asset Management | E39: BNY Mellon Serviços Financeiros | F39: 4 | G39: Crédito High Grade | H39: 1000 | I39: D+29 (corridos) | J39: D+1 (útil) | K39: 30 | L39: 0.0075 | M39: CDI | N39: 37134 | O39: -0.0038845405 | P39: -0.003271529 | Q39: -0.0071828952 | R39: 0.00089583962 | S39: 0.0073676634 | T39: 0.90411903 | U39: 0.95142645 | V39: 1.0077959 | W39: 1.0650162 | X39: 0.0027124757 | Y39: -2.3140899 | Z39: -0.00071626441 | AA39: 24.765175 | AB39: 66.59965 | AC39: 5.7692308 | AD39: 45.769231 | AE39: 33.525011 | AF39: 2 | AG39: 4
A40: Mercado | B40: 43 | C40: Selection RF Light FIC FIRF CP LP | D40: XP Advisory | E40: XP Investimentos | F40: 11 | G40: Crédito High Grade | H40: 100 | I40: D+10 (corridos) | J40: D+2 (útil) | K40: 12 | L40: 0.0031 | M40: CDI | N40: 42607 | O40: -0.0052658926 | P40: -0.0071358774 | Q40: -0.0072454302 | R40: 0.00082693435 | S40: 0.0064639793 | T40: 0.7908639 | U40: 0.95100356 | V40: 1.0071961 | W40: 1.0569978 | X40: 0.0023657838 | Y40: -2.6767627 | Z40: -0.00038159748 | AA40: 18.113553 | AB40: 62.543706 | AC40: 1.9230769 | AD40: 91.538462 | AE40: 33.325487 | AF40: 2 | AG40: 4
...

Sheet Metodologia
A1: Item | B1: Descrição
A2: Universo | B2: Planilha CNC_v1.xlsx enviada pelo usuário, com 53 fundos high grade acessíveis. Linhas amarelas = mercado; linhas verdes = fundos investidos pelo cliente.
A3: Score Retorno Relativo | B3: 45% do score final. Percentil composto das janelas Ano % CDI, 12M % CDI, 24M % CDI e 36M % CDI, com maior peso para 12M e 24M.
A4: Score Risco | B4: 25% do score final. Percentil inverso de volatilidade 12M, drawdown máximo 12M e Risco XP. Menor volatilidade, menor drawdown e menor risco XP recebem maior pontuação.
A5: Score Consistência | B5: 20% do score final. Percentil do Sharpe 12M.
A6: Score Liquidez/Custo | B6: 10% do score final. Percentil inverso de liquidez total e taxa de administração.
A7: Tratamento de dados | B7: Campos em branco ou “-” foram tratados como indisponíveis e reponderados dentro do bloco de score. A análise não substitui due diligence qualitativa de carteira, passivo, concentração por emissor e eventos de crédito.
